Workbook
Name KgVerde: Parametros!$B$6
Name MermaTostado: Parametros!$B$7
Name PesoCuartoG: Parametros!$B$8
Name MermaEmpaque: Parametros!$B$9
Name IVA: Parametros!$B$11
Name PrecioVerdeBase: Parametros!$B$12
Name MaquilaKg: Parametros!$B$13
Name MaquilaSobre: Parametros!$B$14
Name PrecioBolsa: Parametros!$B$15
Name PrecioEtiqueta: Parametros!$B$16
Name PrecioVentaCuarto: Parametros!$B$17
Name FleteLote: Parametros!$B$19
Name MOEmpaqueCuarto: Parametros!$B$20
Name OtrosLote: Parametros!$B$21
Name EscA: Parametros!$B$23
Name EscB: Parametros!$B$24
Name EscC: Parametros!$B$25
Name EscD: Parametros!$B$26
Name EscE: Parametros!$B$27
Name MargenObjetivo: Parametros!$B$29
Name KgTostado: Calc!$B$2
Name KgPorCuarto: Calc!$B$3
Name Cuartos: Calc!$B$4
Name SobranteG: Calc!$B$5
Name Bolsas: Calc!$B$6
Name KgMaquila: Calc!$B$7
Name CostoVerde: Calc!$B$9
Name CostoMaquila: Calc!$B$10
Name CostoBolsas: Calc!$B$11
Name CostoEtiquetas: Calc!$B$12
Name CostoMO: Calc!$B$13
Name CostoFlete: Calc!$B$14
Name CostoOtros: Calc!$B$15
Name CostoTotal: Calc!$B$16
Name CostoSinVerde: Calc!$B$17
Name VentaNeta: Calc!$B$19
Name Utilidad: Calc!$B$20
Name Margen: Calc!$B$21
Name Markup: Calc!$B$22
Name CostoCuarto: Calc!$B$24
Name CostoKgTostado: Calc!$B$25
Name UtilidadCuarto: Calc!$B$26
Name PrecioKgTostadoVenta: Calc!$B$27
Name IvaCredito: Calc!$B$29
Name IvaDebito: Calc!$B$30
Name IvaPagar: Calc!$B$31
Name CajaSalida: Calc!$B$32
Name CajaEntrada: Calc!$B$33
Name FlujoCaja: Calc!$B$34
Name PrecioVerdeMaxCero: Calc!$B$36
Name PrecioVerdeMaxObj: Calc!$B$37
Name VentaMinCuarto: Calc!$B$38
Name VentaMinObj: Calc!$B$39
Name Factible: Calc!$B$40
Name CostoVerdeCuarto: Calc!$B$41
Name CostoMaquilaCuarto: Calc!$B$42
Name CostoBolsaCuarto: Calc!$B$43
Name CostoEtiqCuarto: Calc!$B$44
Name CostoOtrosCuarto: Calc!$B$45
Name Rendimiento: Calc!$B$46

Sheet Como usar
A1: Planilla de factibilidad · cuartos para Tostado Club
A2: Coffee Roasting Labs · Tostaduría Erik Berwart Araya EIRL · RUT 77.586.349-8
A4: Para qué sirve
A5: Decidir si conviene comprar 1.000 kg de café verde, tostarlo (maquila), empacarlo en cuartos de 250 g y vendérselos a Tostado Club a $6.000 + IVA. Compara cinco precios de verde y te dice el margen, la caja que hay que poner y el precio máximo de verde para no perder.
A7: Cómo usarla
A8: 1) Abre Parámetros y revisa las celdas amarillas. 2) Completa bolsas y etiquetas con tu cotización real (hoy hay un supuesto). 3) Mira Resumen: veredicto FACTIBLE / REVISAR. 4) En Escenarios ves $9.000, $9.500, $9.990, $10.000 y $10.500. 5) Sensibilidad sirve si cambia la merma, el precio de la bolsa o si negocias otro precio de venta.
A10: Datos que pediste (ya cargados)
A11: · Compra: 1 tonelada (1.000 kg) de café verde. · Verde: $9.990 + IVA/kg, y escenarios $9.000 / $9.500 / $10.000 / $10.500. · Maquila: $1.500 + IVA/kg (por defecto sobre kg VERDE; cámbialo a Tostado si el maquilador cobra la salida). · Venta: $6.000 + IVA por cuarto de 250 g. · Bolsas y etiquetas: incluidos, con precio supuesto editable.
A15: Supuestos que debes validar
A16: · Merma de tostado 18% (tueste medio). Mídela en el primer batch. · Bolsa $300 + IVA (rango de mercado ~$286 a $700 según proveedor). · Etiqueta $80 + IVA (tiraje de ~3.000 un.). · Se vende el 100% del lote. Flete y mano de obra de empaque en 0 hasta que los cotices. · IVA 19%. Los márgenes se miran NETOS; la caja se mira CON IVA.
A20: Hojas
A21: Resumen — veredicto y números grandes. Parametros — único lugar para editar. Lote 1 tonelada — estado de resultados completo + IVA. Costo por cuarto — de dónde sale cada peso de la bolsa. Escenarios — los 5 precios de verde, lado a lado. Sensibilidad — merma, bolsas y precio de venta.
A26: Documento interno de trabajo. No es una cotización al cliente. Generado 2026-09-04. Cambia las celdas amarillas; no borres nombres definidos ni la hoja Calc (está oculta).

Sheet Resumen
A1: ¿Conviene hacer cuartos para Tostado Club?
A2: Caso base con café verde a $9.990 + IVA/kg · Cambia supuestos en la hoja Parámetros
A4: VEREDICTO (caso base) | E4: Cuartos producidos | G4: Kg tostados
A5: =Factible | E5: =Cuartos | G5: =KgTostado
A7: =IF(Factible="FACTIBLE","El margen neto supera el mínimo de "&TEXT(MargenObjetivo,"0%")&" definido en Parámetros.","El margen queda bajo el mínimo de "&TEXT(MargenObjetivo,"0%")&". Sube precio, baja verde/maquila o empaque.")
A8: Costo por cuarto (neto) | C8: Venta por cuarto (neto) | E8: Utilidad por cuarto | G8: Margen neto
A9: =CostoCuarto | C9: =PrecioVentaCuarto | E9: =UtilidadCuarto | G9: =Margen
A11: Inversión neta del lote | C11: Caja a desembolsar (c/IVA) | E11: Venta neta del lote | G11: Utilidad neta del lote
A12: =CostoTotal | C12: =CajaSalida | E12: =VentaNeta | G12: =Utilidad
A15: Atajo: los 5 precios de café verde (detalle en hoja Escenarios)
B16: A $9.000 | C16: B $9.500 | D16: C $9.990 base | E16: D $10.000 | F16: E $10.500
A17: Utilidad neta lote | B17: =Escenarios!C22 | C17: =Escenarios!D22 | D17: =Escenarios!E22 | E17: =Escenarios!F22 | F17: =Escenarios!G22
A18: Margen neto | B18: =Escenarios!C23 | C18: =Escenarios!D23 | D18: =Escenarios!E23 | E18: =Escenarios!F23 | F18: =Escenarios!G23
A19: ¿Factible? | B19: =Escenarios!C25 | C19: =Escenarios!D25 | D19: =Escenarios!E25 | E19: =Escenarios!F25 | F19: =Escenarios!G25
A20: Costo por cuarto | B20: =Escenarios!C18 | C20: =Escenarios!D18 | D20: =Escenarios!E18 | E20: =Escenarios!F18 | F20: =Escenarios!G18
A22: Umbrales del caso base (con los supuestos actuales)
A23: Precio verde máximo para no perder (utilidad = 0) | E23: =PrecioVerdeMaxCero | G23: $/kg neto
A24: Precio verde máximo para cumplir margen objetivo | E24: =PrecioVerdeMaxObj | G24: $/kg neto
A25: Precio mínimo de venta por cuarto para no perder | E25: =VentaMinCuarto | G25: $/un neto
A26: Precio mínimo de venta por cuarto para margen objetivo | E26: =VentaMinObj | G26: $/un neto
A27: IVA a pagar (débito − crédito) si se vende todo el lote | E27: =IvaPagar | G27: $
A28: Flujo de caja del ciclo (cobro − pago, con IVA) | E28: =FlujoCaja | G28: $
A29: Sobrante de café tostado no empaquetable en cuartos | E29: =SobranteG | G29: g
A31: Lectura comercial (contexto)
A32: Tostado Club vende al público la suscripción de 500 g (2 cuartos) a $23.990 IVA incl., es decir ~$11.995 IVA incl. por cuarto (~$10.080 neto). Si te pagan $6.000 + IVA por cuarto, el cliente se queda con un markup retail típico de club/suscripción y tú con el margen industrial. Esta planilla NO incluye flete ni mano de obra de empaque salvo que los completes en Parámetros. Asume que se vende el 100% de los cuartos del lote. Bolsas y etiquetas son SUPUESTOS: cámbialos apenas tengas cotización real. La merma de tostado mueve mucho el costo por cuarto: mídela en tu primer lote.
A36: Coffee Roasting Labs · RUT 77.586.349-8 · Planilla de trabajo interno · Edita solo celdas amarillas en Parámetros

Sheet Parametros
A1: COFFEE ROASTING LABS · Tostaduría Erik Berwart Araya EIRL
A2: Factibilidad de cuartos (250 g) para Tostado Club · Lote de 1 tonelada de café verde
A3: Celdas amarillas = se editan. El resto de la planilla se recalcula solo. Todos los precios se ingresan NETOS (sin IVA). El IVA se aplica después.
A4: Concepto | B4: Valor (editar) | C4: Unidad | D4: Notas / fuente del supuesto
A5: 1. Volumen y proceso
A6: Kg café verde a comprar | B6: 1000 | C6: kg | D6: Lote pedido: 1 tonelada. Cambia este número si el pedido es otro.
A7: Merma de tostado | B7: 0.18 | C7: % | D7: Pérdida de peso al tostar (humedad + cascarilla). Tueste medio ≈ 16–18%; oscuro ≈ 18–20%. De 1 kg verde quedan ~820 g tostados con 18%.
A8: Peso del cuarto | B8: 250 | C8: g | D8: Bolsa de 250 g de café TOSTADO (no verde).
A9: Merma de empaque extra | B9: 0.02 | C9: % | D9: Bolsas/etiquetas de más por rotura, prueba o error. 0% si compras exacto.
A10: 2. Precios (ingresar NETOS, sin IVA)
A11: IVA | B11: 0.19 | C11: % | D11: IVA Chile vigente. Afecta caja (crédito/débito), no el margen neto.
A12: Precio café verde (caso base) | B12: 9990 | C12: $/kg neto | D12: Dato del negocio: $9.990 + IVA / kg. Los escenarios de abajo se comparan contra este.
A13: Maquila (tostado) | B13: 1500 | C13: $/kg neto | D13: Servicio de tostado: $1.500 + IVA / kg. Ver celda siguiente: ¿se cobra sobre verde o tostado?
A14: Maquila se cobra sobre | B14: Verde | D14: Verde = se multiplica por los kg comprados. Tostado = se multiplica por los kg que salen del tostador.
A15: Bolsa 250 g (válvula / doypack) | B15: 300 | C15: $/un neto | D15: Supuesto editable. Referencias Chile 2026: Funsmart ≈ $286 neto/un (pack 50); Nuestro Café ≈ $600; Cafestore ≈ $700. A granel puede bajar. Pon 0 si las pone Tostado Club.
A16: Etiqueta adhesiva | B16: 80 | C16: $/un neto | D16: Supuesto editable. Referencia imprenta ~$65–$160 + IVA c/u en tirajes de 3.000–4.000. Pon 0 si las pone el cliente.
A17: Precio de venta al cliente (cuarto) | B17: 6000 | C17: $/un neto | D17: Lo que paga Tostado Club: $6.000 + IVA por bolsa de 250 g.
A18: 3. Costos opcionales del lote (neto) — déjalos en 0 si no aplican
A19: Flete / logística del lote | B19: 0 | C19: $ lote neto | D19: Traslado del verde, del tostado o entrega a Tostado Club. Completar cuando tengas cotización.
A20: Mano de obra de empaque | B20: 0 | C20: $/cuarto neto | D20: Si empacas tú: costo de personal por bolsa. 0 si está cubierto o no lo quieres costear aún.
A21: Otros costos del lote | B21: 0 | C21: $ lote neto | D21: Cinta, cajas master, molienda extra, control de calidad, merma de calidad, etc.
A22: 4. Escenarios de precio del café verde (neto, $/kg) — hoja Escenarios
A23: Escenario A | B23: 9000 | C23: $/kg neto | D23: Pedido: ver qué pasa a $9.000 + IVA
A24: Escenario B | B24: 9500 | C24: $/kg neto | D24: Pedido: ver qué pasa a $9.500 + IVA
A25: Escenario C (base) | B25: 9990 | C25: $/kg neto | D25: Precio actual cotizado: $9.990 + IVA
A26: Escenario D | B26: 10000 | C26: $/kg neto | D26: Pedido: ver qué pasa a $10.000 + IVA
A27: Escenario E | B27: 10500 | C27: $/kg neto | D27: Pedido: ver qué pasa a $10.500 + IVA
A28: 5. Criterio de factibilidad
A29: Margen neto mínimo aceptable | B29: 0.25 | C29: % | D29: Si el margen del lote queda bajo este %, el Resumen marca NO FACTIBLE. Ajústalo a tu criterio.

Sheet Lote 1 tonelada
A1: Estado de resultados del lote · caso base
A2: Café verde al precio de Parámetros (hoy $9.990 + IVA/kg) · cifras NETAS salvo donde se indica IVA
A4: A. Conversión de 1 tonelada de café verde a cuartos
A5: Café verde comprado | B5: =KgVerde | D5: kg | F5: Pedido de 1.000 kg (1 tonelada)
A6: Rendimiento de tostado | B6: =Rendimiento | D6: % | F6: 1 − merma
A7: Café tostado obtenido | B7: =KgTostado | D7: kg | F7: Verde × rendimiento
A8: Peso de cada cuarto | B8: =PesoCuartoG | D8: g | F8: Café tostado empacado
A9: Cuartos enteros producidos | B9: =Cuartos | D9: un | F9: Se redondea hacia abajo: no se vende fracción
A10: Sobrante tostado | B10: =SobranteG | D10: g | F10: Queda para muestra, merma o reempaque
A11: Cuartos por kg de verde | B11: =CuartosPorKgVerde | D11: un/kg | F11: Con 18% merma ≈ 3,28 cuartos / kg verde
A12: Bolsas y etiquetas a comprar | B12: =Bolsas | D12: un | F12: Cuartos + merma de empaque
A13: Kg sobre los que se cobra maquila | B13: =KgMaquila | D13: kg | F13: Verde o tostado, según Parámetros
A15: B. Costos del lote (NETOS, sin IVA)
A16: Ítem | B16: Base de cálculo | C16: Precio unit. neto | D16: Costo neto lote | E16: % del costo | F16: Costo por cuarto | G16: Costo c/IVA lote
A17: Café verde | B17: =TEXT(KgVerde,"#,##0")&" kg" | C17: =PrecioVerdeBase | D17: =CostoVerde | E17: =IF(CostoTotal=0,0,D17/CostoTotal) | F17: =CostoVerdeCuarto | G17: =D17*(1+IVA)
A18: Maquila (tostado) | B18: =TEXT(KgMaquila,"#,##0.0")&" kg" | C18: =MaquilaKg | D18: =CostoMaquila | E18: =IF(CostoTotal=0,0,D18/CostoTotal) | F18: =CostoMaquilaCuarto | G18: =D18*(1+IVA)
A19: Bolsas | B19: =TEXT(Bolsas,"#,##0")&" un" | C19: =PrecioBolsa | D19: =CostoBolsas | E19: =IF(CostoTotal=0,0,D19/CostoTotal) | F19: =CostoBolsaCuarto | G19: =D19*(1+IVA)
A20: Etiquetas | B20: =TEXT(Bolsas,"#,##0")&" un" | C20: =PrecioEtiqueta | D20: =CostoEtiquetas | E20: =IF(CostoTotal=0,0,D20/CostoTotal) | F20: =CostoEtiqCuarto | G20: =D20*(1+IVA)
A21: Mano de obra empaque | B21: =TEXT(Cuartos,"#,##0")&" un" | C21: =MOEmpaqueCuarto | D21: =CostoMO | E21: =IF(CostoTotal=0,0,D21/CostoTotal) | F21: =IF(Cuartos=0,0,CostoMO/Cuartos) | G21: =D21*(1+IVA)
A22: Flete / logística | B22: 1 lote | C22: =FleteLote | D22: =CostoFlete | E22: =IF(CostoTotal=0,0,D22/CostoTotal) | F22: =IF(Cuartos=0,0,CostoFlete/Cuartos) | G22: =D22*(1+IVA)
A23: Otros | B23: 1 lote | C23: =OtrosLote | D23: =CostoOtros | E23: =IF(CostoTotal=0,0,D23/CostoTotal) | F23: =IF(Cuartos=0,0,CostoOtros/Cuartos) | G23: =D23*(1+IVA)
A24: TOTAL COSTO LOTE | D24: =CostoTotal | E24: 1 | F24: =CostoCuarto | G24: =CajaSalida
A26: C. Venta, utilidad e IVA (asume venta del 100% de los cuartos)
A27: Cuartos vendidos | B27: =Cuartos
A28: Precio neto por cuarto | B28: =PrecioVentaCuarto
A29: Ingreso neto del lote | B29: =VentaNeta
A30: Costo neto del lote | B30: =CostoTotal
A31: UTILIDAD NETA DEL LOTE | B31: =Utilidad
A32: Margen neto (utilidad / venta) | B32: =Margen
A33: Markup (utilidad / costo) | B33: =Markup
A34: Costo por kg tostado | B34: =CostoKgTostado
A35: Precio de venta por kg tostado | B35: =PrecioKgTostadoVenta
A36: IVA crédito (compras) | B36: =IvaCredito
A37: IVA débito (ventas) | B37: =IvaDebito
A38: IVA a pagar al SII | B38: =IvaPagar
A39: Desembolso de caja (costos + IVA) | B39: =CajaSalida
A40: Cobro de caja (ventas + IVA) | B40: =CajaEntrada
A41: Flujo de caja del ciclo | B41: =FlujoCaja
A43: El IVA no es ganancia ni pérdida: lo recaudas/pagas al SII. El margen que importa para factibilidad es el NETO. La caja sí se ve afectada: compras 1 tonelada de una vez (sale IVA) y cobras cuando factures los cuartos (entra IVA). Si Tostado Club paga a 30 días, hay que financiar el desembolso de caja hasta el cobro.

Sheet Costo por cuarto
A1: Desglose de 1 cuarto de 250 g · caso base
A2: Cada peso del costo se asigna a una bolsa lista para entregar a Tostado Club
A4: Estructura de costo de un cuarto
A5: Componente | B5: $ neto / cuarto | C5: % del costo | D5: % del precio | E5: Gráfico | F5: Comentario
A6: Café verde | B6: =CostoVerdeCuarto | C6: =IF(CostoCuarto=0,0,B6/CostoCuarto) | D6: =IF(PrecioVentaCuarto=0,0,B6/PrecioVentaCuarto) | E6: =C6 | F6: El verde se encarece con la merma: pagas 1 kg y empacas ~820 g.
A7: Maquila | B7: =CostoMaquilaCuarto | C7: =IF(CostoCuarto=0,0,B7/CostoCuarto) | D7: =IF(PrecioVentaCuarto=0,0,B7/PrecioVentaCuarto) | E7: =C7 | F7: Tostado. Si la maquila se cobra sobre verde, también la absorbe la merma.
A8: Bolsa | B8: =CostoBolsaCuarto | C8: =IF(CostoCuarto=0,0,B8/CostoCuarto) | D8: =IF(PrecioVentaCuarto=0,0,B8/PrecioVentaCuarto) | E8: =C8 | F8: Incluye las bolsas extra de merma de empaque prorrateadas.
A9: Etiqueta | B9: =CostoEtiqCuarto | C9: =IF(CostoCuarto=0,0,B9/CostoCuarto) | D9: =IF(PrecioVentaCuarto=0,0,B9/PrecioVentaCuarto) | E9: =C9 | F9: Una etiqueta por bolsa comprada.
A10: MO + flete + otros | B10: =CostoOtrosCuarto | C10: =IF(CostoCuarto=0,0,B10/CostoCuarto) | D10: =IF(PrecioVentaCuarto=0,0,B10/PrecioVentaCuarto) | E10: =C10 | F10: Cero hasta que completes esos campos en Parámetros.
A11: COSTO TOTAL POR CUARTO | B11: =CostoCuarto | C11: 1 | D11: =IF(PrecioVentaCuarto=0,0,CostoCuarto/PrecioVentaCuarto)
A12: PRECIO DE VENTA | B12: =PrecioVentaCuarto | D12: 1
A13: UTILIDAD POR CUARTO | B13: =UtilidadCuarto | D13: =Margen
A31: Regla rápida: con merma 18%, cada kg verde rinde 3,28 cuartos. Costo verde por cuarto ≈ precio_verde / 3,28. A $9.990 eso es ~$3.046 de verde por bolsa, antes de maquila y empaque. Si la merma sube a 20%, rinde 3,20 cuartos y el verde por bolsa sube a ~$3.122.

Sheet Escenarios
A1: Escenarios de precio del café verde
A2: Misma tonelada, misma maquila, mismas bolsas/etiquetas. Solo cambia el $/kg neto del verde.
A4: Los precios de cada columna se editan en Parámetros filas 23–27. El resto (merma, maquila, empaque, venta) se toma de Parámetros.
A6: Indicador | B6: Unidad | C6: A | D6: B | E6: C base | F6: D | G6: E
A7: Precio café verde | B7: $/kg neto | C7: =EscA | D7: =EscB | E7: =EscC | F7: =EscD | G7: =EscE | H7: Editar en Parámetros
A8: Costo café verde | B8: $ neto | C8: =KgVerde*C7 | D8: =KgVerde*D7 | E8: =KgVerde*E7 | F8: =KgVerde*F7 | G8: =KgVerde*G7
A9: Maquila + empaque + otros | B9: $ neto | C9: =CostoSinVerde | D9: =CostoSinVerde | E9: =CostoSinVerde | F9: =CostoSinVerde | G9: =CostoSinVerde
A10: Costo total lote | B10: $ neto | C10: =C8+C9 | D10: =D8+D9 | E10: =E8+E9 | F10: =F8+F9 | G10: =G8+G9
A11: Costo total lote c/IVA | B11: $ | C11: =C10*(1+IVA) | D11: =D10*(1+IVA) | E11: =E10*(1+IVA) | F11: =F10*(1+IVA) | G11: =G10*(1+IVA)
A12: Kg tostados | B12: kg | C12: =KgTostado | D12: =KgTostado | E12: =KgTostado | F12: =KgTostado | G12: =KgTostado
A13: Cuartos producidos | B13: un | C13: =Cuartos | D13: =Cuartos | E13: =Cuartos | F13: =Cuartos | G13: =Cuartos
A14: Ingreso neto (venta 100%) | B14: $ neto | C14: =VentaNeta | D14: =VentaNeta | E14: =VentaNeta | F14: =VentaNeta | G14: =VentaNeta
A15: Ingreso c/IVA | B15: $ | C15: =CajaEntrada | D15: =CajaEntrada | E15: =CajaEntrada | F15: =CajaEntrada | G15: =CajaEntrada
A17: Costo por kg tostado | B17: $/kg neto | C17: =IF(KgTostado=0,0,C10/KgTostado) | D17: =IF(KgTostado=0,0,D10/KgTostado) | E17: =IF(KgTostado=0,0,E10/KgTostado) | F17: =IF(KgTostado=0,0,F10/KgTostado) | G17: =IF(KgTostado=0,0,G10/KgTostado)
A18: Costo por cuarto | B18: $/un neto | C18: =IF(Cuartos=0,0,C10/Cuartos) | D18: =IF(Cuartos=0,0,D10/Cuartos) | E18: =IF(Cuartos=0,0,E10/Cuartos) | F18: =IF(Cuartos=0,0,F10/Cuartos) | G18: =IF(Cuartos=0,0,G10/Cuartos)
A19: Utilidad por cuarto | B19: $/un neto | C19: =PrecioVentaCuarto-C18 | D19: =PrecioVentaCuarto-D18 | E19: =PrecioVentaCuarto-E18 | F19: =PrecioVentaCuarto-F18 | G19: =PrecioVentaCuarto-G18
A20: Café verde por cuarto | B20: $/un neto | C20: =IF(Cuartos=0,0,C8/Cuartos) | D20: =IF(Cuartos=0,0,D8/Cuartos) | E20: =IF(Cuartos=0,0,E8/Cuartos) | F20: =IF(Cuartos=0,0,F8/Cuartos) | G20: =IF(Cuartos=0,0,G8/Cuartos)
A22: UTILIDAD NETA DEL LOTE | B22: $ neto | C22: =C14-C10 | D22: =D14-D10 | E22: =E14-E10 | F22: =F14-F10 | G22: =G14-G10
A23: Margen neto | B23: % | C23: =IF(C14=0,0,C22/C14) | D23: =IF(D14=0,0,D22/D14) | E23: =IF(E14=0,0,E22/E14) | F23: =IF(F14=0,0,F22/F14) | G23: =IF(G14=0,0,G22/G14)
A24: Markup sobre costo | B24: % | C24: =IF(C10=0,0,C22/C10) | D24: =IF(D10=0,0,D22/D10) | E24: =IF(E10=0,0,E22/E10) | F24: =IF(F10=0,0,F22/F10) | G24: =IF(G10=0,0,G22/G10)
A25: ¿Cumple margen objetivo? | B25: SÍ / NO | C25: =IF(C23>=MargenObjetivo,"SÍ","NO") | D25: =IF(D23>=MargenObjetivo,"SÍ","NO") | E25: =IF(E23>=MargenObjetivo,"SÍ","NO") | F25: =IF(F23>=MargenObjetivo,"SÍ","NO") | G25: =IF(G23>=MargenObjetivo,"SÍ","NO")
A27: IVA crédito | B27: $ | C27: =C10*IVA | D27: =D10*IVA | E27: =E10*IVA | F27: =F10*IVA | G27: =G10*IVA
A28: IVA débito | B28: $ | C28: =IvaDebito | D28: =IvaDebito | E28: =IvaDebito | F28: =IvaDebito | G28: =IvaDebito
A29: IVA a pagar | B29: $ | C29: =C28-C27 | D29: =D28-D27 | E29: =E28-E27 | F29: =F28-F27 | G29: =G28-G27
A30: Flujo de caja del ciclo | B30: $ | C30: =C15-C11 | D30: =D15-D11 | E30: =E15-E11 | F30: =F15-F11 | G30: =G15-G11
A31: Utilidad neta / kg verde | B31: $/kg | C31: =IF(KgVerde=0,0,C22/KgVerde) | D31: =IF(KgVerde=0,0,D22/KgVerde) | E31: =IF(KgVerde=0,0,E22/KgVerde) | F31: =IF(KgVerde=0,0,F22/KgVerde) | G31: =IF(KgVerde=0,0,G22/KgVerde)
A32: ROI sobre costo neto | B32: % | C32: =IF(C10=0,0,C22/C10) | D32: =IF(D10=0,0,D22/D10) | E32: =IF(E10=0,0,E22/E10) | F32: =IF(F10=0,0,F22/F10) | G32: =IF(G10=0,0,G22/G10)
A66: Cómo leerlo: si todos los escenarios salen SÍ, el negocio aguanta bien una subida del verde hasta $10.500. Si alguno sale NO, ese precio ya no cumple tu margen mínimo de Parámetros. Compara también el desembolso de caja (fila 11): es lo que hay que tener disponible para comprar la tonelada, tostar y empacar.

Sheet Sensibilidad
A1: Sensibilidad extra · merma, bolsas y precio de venta
A2: Tablas que se recalculan con Parámetros. Útiles si aún no cierras cotización de empaque o el perfil de tueste.
A4: 1. Utilidad neta del lote: precio verde (filas) × merma de tostado (columnas)
A5: Verde \ Merma | B5: 0.14 | C5: 0.16 | D5: 0.18 | E5: 0.2 | F5: 0.22 | G5: Lectura
A6: =EscA | B6: =((IF((PesoCuartoG/1000)=0,0,INT((KgVerde*(1-B$5))/(PesoCuartoG/1000))))*PrecioVentaCuarto)-(KgVerde*$A6+(IF(MaquilaSobre="Tostado",(KgVerde*(1-B$5)),KgVerde))*MaquilaKg+(ROUNDUP((IF((PesoCuartoG/1000)=0,0,INT((KgVerde*(1-B$5))/(PesoCuartoG/1000))))*(1+MermaEmpaque),0))*(PrecioBolsa+PrecioEtiqueta)+(IF((PesoCuartoG/1000)=0,0,INT((KgVerde*(1-B$5))/(PesoCuartoG/1000))))*MOEmpaqueCuarto+FleteLote+OtrosLote) | C6: =((IF((PesoCuartoG/1000)=0,0,INT((KgVerde*(1-C$5))/(PesoCuartoG/1000))))*PrecioVentaCuarto)-(KgVerde*$A6+(IF(MaquilaSobre="Tostado",(KgVerde*(1-C$5)),KgVerde))*MaquilaKg+(ROUNDUP((IF((PesoCuartoG/1000)=0,0,INT((KgVerde*(1-C$5))/(PesoCuartoG/1000))))*(1+MermaEmpaque),0))*(PrecioBolsa+PrecioEtiqueta)+(IF((PesoCuartoG/1000)=0,0,INT((KgVerde*(1-C$5))/(PesoCuartoG/1000))))*MOEmpaqueCuarto+FleteLote+OtrosLote) | D6: =((IF((PesoCuartoG/1000)=0,0,INT((KgVerde*(1-D$5))/(PesoCuartoG/1000))))*PrecioVentaCuarto)-(KgVerde*$A6+(IF(MaquilaSobre="Tostado",(KgVerde*(1-D$5)),KgVerde))*MaquilaKg+(ROUNDUP((IF((PesoCuartoG/1000)=0,0,INT((KgVerde*(1-D$5))/(PesoCuartoG/1000))))*(1+MermaEmpaque),0))*(PrecioBolsa+PrecioEtiqueta)+(IF((PesoCuartoG/1000)=0,0,INT((KgVerde*(1-D$5))/(PesoCuartoG/1000))))*MOEmpaqueCuarto+FleteLote+OtrosLote) | E6: =((IF((PesoCuartoG/1000)=0,0,INT((KgVerde*(1-E$5))/(PesoCuartoG/1000))))*PrecioVentaCuarto)-(KgVerde*$A6+(IF(MaquilaSobre="Tostado",(KgVerde*(1-E$5)),KgVerde))*MaquilaKg+(ROUNDUP((IF((PesoCuartoG/1000)=0,0,INT((KgVerde*(1-E$5))/(PesoCuartoG/1000))))*(1+MermaEmpaque),0))*(PrecioBolsa+PrecioEtiqueta)+(IF((PesoCuartoG/1000)=0,0,INT((KgVerde*(1-E$5))/(PesoCuartoG/1000))))*MOEmpaqueCuarto+FleteLote+OtrosLote) | F6: =((IF((PesoCuartoG/1000)=0,0,INT((KgVerde*(1-F$5))/(PesoCuartoG/1000))))*PrecioVentaCuarto)-(KgVerde*$A6+(IF(MaquilaSobre="Tostado",(KgVerde*(1-F$5)),KgVerde))*MaquilaKg+(ROUNDUP((IF((PesoCuartoG/1000)=0,0,INT((KgVerde*(1-F$5))/(PesoCuartoG/1000))))*(1+MermaEmpaque),0))*(PrecioBolsa+PrecioEtiqueta)+(IF((PesoCuartoG/1000)=0,0,INT((KgVerde*(1-F$5))/(PesoCuartoG/1000))))*MOEmpaqueCuarto+FleteLote+OtrosLote) | G6: Más merma = menos cuartos = menos venta y el verde se reparte en menos bolsas.
A7: =EscB | B7: =((IF((PesoCuartoG/1000)=0,0,INT((KgVerde*(1-B$5))/(PesoCuartoG/1000))))*PrecioVentaCuarto)-(KgVerde*$A7+(IF(MaquilaSobre="Tostado",(KgVerde*(1-B$5)),KgVerde))*MaquilaKg+(ROUNDUP((IF((PesoCuartoG/1000)=0,0,INT((KgVerde*(1-B$5))/(PesoCuartoG/1000))))*(1+MermaEmpaque),0))*(PrecioBolsa+PrecioEtiqueta)+(IF((PesoCuartoG/1000)=0,0,INT((KgVerde*(1-B$5))/(PesoCuartoG/1000))))*MOEmpaqueCuarto+FleteLote+OtrosLote) | C7: =((IF((PesoCuartoG/1000)=0,0,INT((KgVerde*(1-C$5))/(PesoCuartoG/1000))))*PrecioVentaCuarto)-(KgVerde*$A7+(IF(MaquilaSobre="Tostado",(KgVerde*(1-C$5)),KgVerde))*MaquilaKg+(ROUNDUP((IF((PesoCuartoG/1000)=0,0,INT((KgVerde*(1-C$5))/(PesoCuartoG/1000))))*(1+MermaEmpaque),0))*(PrecioBolsa+PrecioEtiqueta)+(IF((PesoCuartoG/1000)=0,0,INT((KgVerde*(1-C$5))/(PesoCuartoG/1000))))*MOEmpaqueCuarto+FleteLote+OtrosLote) | D7: =((IF((PesoCuartoG/1000)=0,0,INT((KgVerde*(1-D$5))/(PesoCuartoG/1000))))*PrecioVentaCuarto)-(KgVerde*$A7+(IF(MaquilaSobre="Tostado",(KgVerde*(1-D$5)),KgVerde))*MaquilaKg+(ROUNDUP((IF((PesoCuartoG/1000)=0,0,INT((KgVerde*(1-D$5))/(PesoCuartoG/1000))))*(1+MermaEmpaque),0))*(PrecioBolsa+PrecioEtiqueta)+(IF((PesoCuartoG/1000)=0,0,INT((KgVerde*(1-D$5))/(PesoCuartoG/1000))))*MOEmpaqueCuarto+FleteLote+OtrosLote) | E7: =((IF((PesoCuartoG/1000)=0,0,INT((KgVerde*(1-E$5))/(PesoCuartoG/1000))))*PrecioVentaCuarto)-(KgVerde*$A7+(IF(MaquilaSobre="Tostado",(KgVerde*(1-E$5)),KgVerde))*MaquilaKg+(ROUNDUP((IF((PesoCuartoG/1000)=0,0,INT((KgVerde*(1-E$5))/(PesoCuartoG/1000))))*(1+MermaEmpaque),0))*(PrecioBolsa+PrecioEtiqueta)+(IF((PesoCuartoG/1000)=0,0,INT((KgVerde*(1-E$5))/(PesoCuartoG/1000))))*MOEmpaqueCuarto+FleteLote+OtrosLote) | F7: =((IF((PesoCuartoG/1000)=0,0,INT((KgVerde*(1-F$5))/(PesoCuartoG/1000))))*PrecioVentaCuarto)-(KgVerde*$A7+(IF(MaquilaSobre="Tostado",(KgVerde*(1-F$5)),KgVerde))*MaquilaKg+(ROUNDUP((IF((PesoCuartoG/1000)=0,0,INT((KgVerde*(1-F$5))/(PesoCuartoG/1000))))*(1+MermaEmpaque),0))*(PrecioBolsa+PrecioEtiqueta)+(IF((PesoCuartoG/1000)=0,0,INT((KgVerde*(1-F$5))/(PesoCuartoG/1000))))*MOEmpaqueCuarto+FleteLote+OtrosLote)
A8: =EscC | B8: =((IF((PesoCuartoG/1000)=0,0,INT((KgVerde*(1-B$5))/(PesoCuartoG/1000))))*PrecioVentaCuarto)-(KgVerde*$A8+(IF(MaquilaSobre="Tostado",(KgVerde*(1-B$5)),KgVerde))*MaquilaKg+(ROUNDUP((IF((PesoCuartoG/1000)=0,0,INT((KgVerde*(1-B$5))/(PesoCuartoG/1000))))*(1+MermaEmpaque),0))*(PrecioBolsa+PrecioEtiqueta)+(IF((PesoCuartoG/1000)=0,0,INT((KgVerde*(1-B$5))/(PesoCuartoG/1000))))*MOEmpaqueCuarto+FleteLote+OtrosLote) | C8: =((IF((PesoCuartoG/1000)=0,0,INT((KgVerde*(1-C$5))/(PesoCuartoG/1000))))*PrecioVentaCuarto)-(KgVerde*$A8+(IF(MaquilaSobre="Tostado",(KgVerde*(1-C$5)),KgVerde))*MaquilaKg+(ROUNDUP((IF((PesoCuartoG/1000)=0,0,INT((KgVerde*(1-C$5))/(PesoCuartoG/1000))))*(1+MermaEmpaque),0))*(PrecioBolsa+PrecioEtiqueta)+(IF((PesoCuartoG/1000)=0,0,INT((KgVerde*(1-C$5))/(PesoCuartoG/1000))))*MOEmpaqueCuarto+FleteLote+OtrosLote) | D8: =((IF((PesoCuartoG/1000)=0,0,INT((KgVerde*(1-D$5))/(PesoCuartoG/1000))))*PrecioVentaCuarto)-(KgVerde*$A8+(IF(MaquilaSobre="Tostado",(KgVerde*(1-D$5)),KgVerde))*MaquilaKg+(ROUNDUP((IF((PesoCuartoG/1000)=0,0,INT((KgVerde*(1-D$5))/(PesoCuartoG/1000))))*(1+MermaEmpaque),0))*(PrecioBolsa+PrecioEtiqueta)+(IF((PesoCuartoG/1000)=0,0,INT((KgVerde*(1-D$5))/(PesoCuartoG/1000))))*MOEmpaqueCuarto+FleteLote+OtrosLote) | E8: =((IF((PesoCuartoG/1000)=0,0,INT((KgVerde*(1-E$5))/(PesoCuartoG/1000))))*PrecioVentaCuarto)-(KgVerde*$A8+(IF(MaquilaSobre="Tostado",(KgVerde*(1-E$5)),KgVerde))*MaquilaKg+(ROUNDUP((IF((PesoCuartoG/1000)=0,0,INT((KgVerde*(1-E$5))/(PesoCuartoG/1000))))*(1+MermaEmpaque),0))*(PrecioBolsa+PrecioEtiqueta)+(IF((PesoCuartoG/1000)=0,0,INT((KgVerde*(1-E$5))/(PesoCuartoG/1000))))*MOEmpaqueCuarto+FleteLote+OtrosLote) | F8: =((IF((PesoCuartoG/1000)=0,0,INT((KgVerde*(1-F$5))/(PesoCuartoG/1000))))*PrecioVentaCuarto)-(KgVerde*$A8+(IF(MaquilaSobre="Tostado",(KgVerde*(1-F$5)),KgVerde))*MaquilaKg+(ROUNDUP((IF((PesoCuartoG/1000)=0,0,INT((KgVerde*(1-F$5))/(PesoCuartoG/1000))))*(1+MermaEmpaque),0))*(PrecioBolsa+PrecioEtiqueta)+(IF((PesoCuartoG/1000)=0,0,INT((KgVerde*(1-F$5))/(PesoCuartoG/1000))))*MOEmpaqueCuarto+FleteLote+OtrosLote)
A9: =EscD | B9: =((IF((PesoCuartoG/1000)=0,0,INT((KgVerde*(1-B$5))/(PesoCuartoG/1000))))*PrecioVentaCuarto)-(KgVerde*$A9+(IF(MaquilaSobre="Tostado",(KgVerde*(1-B$5)),KgVerde))*MaquilaKg+(ROUNDUP((IF((PesoCuartoG/1000)=0,0,INT((KgVerde*(1-B$5))/(PesoCuartoG/1000))))*(1+MermaEmpaque),0))*(PrecioBolsa+PrecioEtiqueta)+(IF((PesoCuartoG/1000)=0,0,INT((KgVerde*(1-B$5))/(PesoCuartoG/1000))))*MOEmpaqueCuarto+FleteLote+OtrosLote) | C9: =((IF((PesoCuartoG/1000)=0,0,INT((KgVerde*(1-C$5))/(PesoCuartoG/1000))))*PrecioVentaCuarto)-(KgVerde*$A9+(IF(MaquilaSobre="Tostado",(KgVerde*(1-C$5)),KgVerde))*MaquilaKg+(ROUNDUP((IF((PesoCuartoG/1000)=0,0,INT((KgVerde*(1-C$5))/(PesoCuartoG/1000))))*(1+MermaEmpaque),0))*(PrecioBolsa+PrecioEtiqueta)+(IF((PesoCuartoG/1000)=0,0,INT((KgVerde*(1-C$5))/(PesoCuartoG/1000))))*MOEmpaqueCuarto+FleteLote+OtrosLote) | D9: =((IF((PesoCuartoG/1000)=0,0,INT((KgVerde*(1-D$5))/(PesoCuartoG/1000))))*PrecioVentaCuarto)-(KgVerde*$A9+(IF(MaquilaSobre="Tostado",(KgVerde*(1-D$5)),KgVerde))*MaquilaKg+(ROUNDUP((IF((PesoCuartoG/1000)=0,0,INT((KgVerde*(1-D$5))/(PesoCuartoG/1000))))*(1+MermaEmpaque),0))*(PrecioBolsa+PrecioEtiqueta)+(IF((PesoCuartoG/1000)=0,0,INT((KgVerde*(1-D$5))/(PesoCuartoG/1000))))*MOEmpaqueCuarto+FleteLote+OtrosLote) | E9: =((IF((PesoCuartoG/1000)=0,0,INT((KgVerde*(1-E$5))/(PesoCuartoG/1000))))*PrecioVentaCuarto)-(KgVerde*$A9+(IF(MaquilaSobre="Tostado",(KgVerde*(1-E$5)),KgVerde))*MaquilaKg+(ROUNDUP((IF((PesoCuartoG/1000)=0,0,INT((KgVerde*(1-E$5))/(PesoCuartoG/1000))))*(1+MermaEmpaque),0))*(PrecioBolsa+PrecioEtiqueta)+(IF((PesoCuartoG/1000)=0,0,INT((KgVerde*(1-E$5))/(PesoCuartoG/1000))))*MOEmpaqueCuarto+FleteLote+OtrosLote) | F9: =((IF((PesoCuartoG/1000)=0,0,INT((KgVerde*(1-F$5))/(PesoCuartoG/1000))))*PrecioVentaCuarto)-(KgVerde*$A9+(IF(MaquilaSobre="Tostado",(KgVerde*(1-F$5)),KgVerde))*MaquilaKg+(ROUNDUP((IF((PesoCuartoG/1000)=0,0,INT((KgVerde*(1-F$5))/(PesoCuartoG/1000))))*(1+MermaEmpaque),0))*(PrecioBolsa+PrecioEtiqueta)+(IF((PesoCuartoG/1000)=0,0,INT((KgVerde*(1-F$5))/(PesoCuartoG/1000))))*MOEmpaqueCuarto+FleteLote+OtrosLote)
A10: =EscE | B10: =((IF((PesoCuartoG/1000)=0,0,INT((KgVerde*(1-B$5))/(PesoCuartoG/1000))))*PrecioVentaCuarto)-(KgVerde*$A10+(IF(MaquilaSobre="Tostado",(KgVerde*(1-B$5)),KgVerde))*MaquilaKg+(ROUNDUP((IF((PesoCuartoG/1000)=0,0,INT((KgVerde*(1-B$5))/(PesoCuartoG/1000))))*(1+MermaEmpaque),0))*(PrecioBolsa+PrecioEtiqueta)+(IF((PesoCuartoG/1000)=0,0,INT((KgVerde*(1-B$5))/(PesoCuartoG/1000))))*MOEmpaqueCuarto+FleteLote+OtrosLote) | C10: =((IF((PesoCuartoG/1000)=0,0,INT((KgVerde*(1-C$5))/(PesoCuartoG/1000))))*PrecioVentaCuarto)-(KgVerde*$A10+(IF(MaquilaSobre="Tostado",(KgVerde*(1-C$5)),KgVerde))*MaquilaKg+(ROUNDUP((IF((PesoCuartoG/1000)=0,0,INT((KgVerde*(1-C$5))/(PesoCuartoG/1000))))*(1+MermaEmpaque),0))*(PrecioBolsa+PrecioEtiqueta)+(IF((PesoCuartoG/1000)=0,0,INT((KgVerde*(1-C$5))/(PesoCuartoG/1000))))*MOEmpaqueCuarto+FleteLote+OtrosLote) | D10: =((IF((PesoCuartoG/1000)=0,0,INT((KgVerde*(1-D$5))/(PesoCuartoG/1000))))*PrecioVentaCuarto)-(KgVerde*$A10+(IF(MaquilaSobre="Tostado",(KgVerde*(1-D$5)),KgVerde))*MaquilaKg+(ROUNDUP((IF((PesoCuartoG/1000)=0,0,INT((KgVerde*(1-D$5))/(PesoCuartoG/1000))))*(1+MermaEmpaque),0))*(PrecioBolsa+PrecioEtiqueta)+(IF((PesoCuartoG/1000)=0,0,INT((KgVerde*(1-D$5))/(PesoCuartoG/1000))))*MOEmpaqueCuarto+FleteLote+OtrosLote) | E10: =((IF((PesoCuartoG/1000)=0,0,INT((KgVerde*(1-E$5))/(PesoCuartoG/1000))))*PrecioVentaCuarto)-(KgVerde*$A10+(IF(MaquilaSobre="Tostado",(KgVerde*(1-E$5)),KgVerde))*MaquilaKg+(ROUNDUP((IF((PesoCuartoG/1000)=0,0,INT((KgVerde*(1-E$5))/(PesoCuartoG/1000))))*(1+MermaEmpaque),0))*(PrecioBolsa+PrecioEtiqueta)+(IF((PesoCuartoG/1000)=0,0,INT((KgVerde*(1-E$5))/(PesoCuartoG/1000))))*MOEmpaqueCuarto+FleteLote+OtrosLote) | F10: =((IF((PesoCuartoG/1000)=0,0,INT((KgVerde*(1-F$5))/(PesoCuartoG/1000))))*PrecioVentaCuarto)-(KgVerde*$A10+(IF(MaquilaSobre="Tostado",(KgVerde*(1-F$5)),KgVerde))*MaquilaKg+(ROUNDUP((IF((PesoCuartoG/1000)=0,0,INT((KgVerde*(1-F$5))/(PesoCuartoG/1000))))*(1+MermaEmpaque),0))*(PrecioBolsa+PrecioEtiqueta)+(IF((PesoCuartoG/1000)=0,0,INT((KgVerde*(1-F$5))/(PesoCuartoG/1000))))*MOEmpaqueCuarto+FleteLote+OtrosLote)
A12: 2. Utilidad neta del lote: precio verde × costo de bolsa neta (la etiqueta se mantiene)
A13: Verde \ Bolsa | B13: 0 | C13: 200 | D13: 300 | E13: 500 | F13: 700 | G13: 0 = las pone Tostado Club. $700 ≈ Cafestore. $300 ≈ Funsmart a volumen.
A14: =EscA | B14: =((IF((PesoCuartoG/1000)=0,0,INT((KgVerde*(1-MermaTostado))/(PesoCuartoG/1000))))*PrecioVentaCuarto)-(KgVerde*$A14+(IF(MaquilaSobre="Tostado",(KgVerde*(1-MermaTostado)),KgVerde))*MaquilaKg+(ROUNDUP((IF((PesoCuartoG/1000)=0,0,INT((KgVerde*(1-MermaTostado))/(PesoCuartoG/1000))))*(1+MermaEmpaque),0))*(B$13+PrecioEtiqueta)+(IF((PesoCuartoG/1000)=0,0,INT((KgVerde*(1-MermaTostado))/(PesoCuartoG/1000))))*MOEmpaqueCuarto+FleteLote+OtrosLote) | C14: =((IF((PesoCuartoG/1000)=0,0,INT((KgVerde*(1-MermaTostado))/(PesoCuartoG/1000))))*PrecioVentaCuarto)-(KgVerde*$A14+(IF(MaquilaSobre="Tostado",(KgVerde*(1-MermaTostado)),KgVerde))*MaquilaKg+(ROUNDUP((IF((PesoCuartoG/1000)=0,0,INT((KgVerde*(1-MermaTostado))/(PesoCuartoG/1000))))*(1+MermaEmpaque),0))*(C$13+PrecioEtiqueta)+(IF((PesoCuartoG/1000)=0,0,INT((KgVerde*(1-MermaTostado))/(PesoCuartoG/1000))))*MOEmpaqueCuarto+FleteLote+OtrosLote) | D14: =((IF((PesoCuartoG/1000)=0,0,INT((KgVerde*(1-MermaTostado))/(PesoCuartoG/1000))))*PrecioVentaCuarto)-(KgVerde*$A14+(IF(MaquilaSobre="Tostado",(KgVerde*(1-MermaTostado)),KgVerde))*MaquilaKg+(ROUNDUP((IF((PesoCuartoG/1000)=0,0,INT((KgVerde*(1-MermaTostado))/(PesoCuartoG/1000))))*(1+MermaEmpaque),0))*(D$13+PrecioEtiqueta)+(IF((PesoCuartoG/1000)=0,0,INT((KgVerde*(1-MermaTostado))/(PesoCuartoG/1000))))*MOEmpaqueCuarto+FleteLote+OtrosLote) | E14: =((IF((PesoCuartoG/1000)=0,0,INT((KgVerde*(1-MermaTostado))/(PesoCuartoG/1000))))*PrecioVentaCuarto)-(KgVerde*$A14+(IF(MaquilaSobre="Tostado",(KgVerde*(1-MermaTostado)),KgVerde))*MaquilaKg+(ROUNDUP((IF((PesoCuartoG/1000)=0,0,INT((KgVerde*(1-MermaTostado))/(PesoCuartoG/1000))))*(1+MermaEmpaque),0))*(E$13+PrecioEtiqueta)+(IF((PesoCuartoG/1000)=0,0,INT((KgVerde*(1-MermaTostado))/(PesoCuartoG/1000))))*MOEmpaqueCuarto+FleteLote+OtrosLote) | F14: =((IF((PesoCuartoG/1000)=0,0,INT((KgVerde*(1-MermaTostado))/(PesoCuartoG/1000))))*PrecioVentaCuarto)-(KgVerde*$A14+(IF(MaquilaSobre="Tostado",(KgVerde*(1-MermaTostado)),KgVerde))*MaquilaKg+(ROUNDUP((IF((PesoCuartoG/1000)=0,0,INT((KgVerde*(1-MermaTostado))/(PesoCuartoG/1000))))*(1+MermaEmpaque),0))*(F$13+PrecioEtiqueta)+(IF((PesoCuartoG/1000)=0,0,INT((KgVerde*(1-MermaTostado))/(PesoCuartoG/1000))))*MOEmpaqueCuarto+FleteLote+OtrosLote)
A15: =EscB | B15: =((IF((PesoCuartoG/1000)=0,0,INT((KgVerde*(1-MermaTostado))/(PesoCuartoG/1000))))*PrecioVentaCuarto)-(KgVerde*$A15+(IF(MaquilaSobre="Tostado",(KgVerde*(1-MermaTostado)),KgVerde))*MaquilaKg+(ROUNDUP((IF((PesoCuartoG/1000)=0,0,INT((KgVerde*(1-MermaTostado))/(PesoCuartoG/1000))))*(1+MermaEmpaque),0))*(B$13+PrecioEtiqueta)+(IF((PesoCuartoG/1000)=0,0,INT((KgVerde*(1-MermaTostado))/(PesoCuartoG/1000))))*MOEmpaqueCuarto+FleteLote+OtrosLote) | C15: =((IF((PesoCuartoG/1000)=0,0,INT((KgVerde*(1-MermaTostado))/(PesoCuartoG/1000))))*PrecioVentaCuarto)-(KgVerde*$A15+(IF(MaquilaSobre="Tostado",(KgVerde*(1-MermaTostado)),KgVerde))*MaquilaKg+(ROUNDUP((IF((PesoCuartoG/1000)=0,0,INT((KgVerde*(1-MermaTostado))/(PesoCuartoG/1000))))*(1+MermaEmpaque),0))*(C$13+PrecioEtiqueta)+(IF((PesoCuartoG/1000)=0,0,INT((KgVerde*(1-MermaTostado))/(PesoCuartoG/1000))))*MOEmpaqueCuarto+FleteLote+OtrosLote) | D15: =((IF((PesoCuartoG/1000)=0,0,INT((KgVerde*(1-MermaTostado))/(PesoCuartoG/1000))))*PrecioVentaCuarto)-(KgVerde*$A15+(IF(MaquilaSobre="Tostado",(KgVerde*(1-MermaTostado)),KgVerde))*MaquilaKg+(ROUNDUP((IF((PesoCuartoG/1000)=0,0,INT((KgVerde*(1-MermaTostado))/(PesoCuartoG/1000))))*(1+MermaEmpaque),0))*(D$13+PrecioEtiqueta)+(IF((PesoCuartoG/1000)=0,0,INT((KgVerde*(1-MermaTostado))/(PesoCuartoG/1000))))*MOEmpaqueCuarto+FleteLote+OtrosLote) | E15: =((IF((PesoCuartoG/1000)=0,0,INT((KgVerde*(1-MermaTostado))/(PesoCuartoG/1000))))*PrecioVentaCuarto)-(KgVerde*$A15+(IF(MaquilaSobre="Tostado",(KgVerde*(1-MermaTostado)),KgVerde))*MaquilaKg+(ROUNDUP((IF((PesoCuartoG/1000)=0,0,INT((KgVerde*(1-MermaTostado))/(PesoCuartoG/1000))))*(1+MermaEmpaque),0))*(E$13+PrecioEtiqueta)+(IF((PesoCuartoG/1000)=0,0,INT((KgVerde*(1-MermaTostado))/(PesoCuartoG/1000))))*MOEmpaqueCuarto+FleteLote+OtrosLote) | F15: =((IF((PesoCuartoG/1000)=0,0,INT((KgVerde*(1-MermaTostado))/(PesoCuartoG/1000))))*PrecioVentaCuarto)-(KgVerde*$A15+(IF(MaquilaSobre="Tostado",(KgVerde*(1-MermaTostado)),KgVerde))*MaquilaKg+(ROUNDUP((IF((PesoCuartoG/1000)=0,0,INT((KgVerde*(1-MermaTostado))/(PesoCuartoG/1000))))*(1+MermaEmpaque),0))*(F$13+PrecioEtiqueta)+(IF((PesoCuartoG/1000)=0,0,INT((KgVerde*(1-MermaTostado))/(PesoCuartoG/1000))))*MOEmpaqueCuarto+FleteLote+OtrosLote)
A16: =EscC | B16: =((IF((PesoCuartoG/1000)=0,0,INT((KgVerde*(1-MermaTostado))/(PesoCuartoG/1000))))*PrecioVentaCuarto)-(KgVerde*$A16+(IF(MaquilaSobre="Tostado",(KgVerde*(1-MermaTostado)),KgVerde))*MaquilaKg+(ROUNDUP((IF((PesoCuartoG/1000)=0,0,INT((KgVerde*(1-MermaTostado))/(PesoCuartoG/1000))))*(1+MermaEmpaque),0))*(B$13+PrecioEtiqueta)+(IF((PesoCuartoG/1000)=0,0,INT((KgVerde*(1-MermaTostado))/(PesoCuartoG/1000))))*MOEmpaqueCuarto+FleteLote+OtrosLote) | C16: =((IF((PesoCuartoG/1000)=0,0,INT((KgVerde*(1-MermaTostado))/(PesoCuartoG/1000))))*PrecioVentaCuarto)-(KgVerde*$A16+(IF(MaquilaSobre="Tostado",(KgVerde*(1-MermaTostado)),KgVerde))*MaquilaKg+(ROUNDUP((IF((PesoCuartoG/1000)=0,0,INT((KgVerde*(1-MermaTostado))/(PesoCuartoG/1000))))*(1+MermaEmpaque),0))*(C$13+PrecioEtiqueta)+(IF((PesoCuartoG/1000)=0,0,INT((KgVerde*(1-MermaTostado))/(PesoCuartoG/1000))))*MOEmpaqueCuarto+FleteLote+OtrosLote) | D16: =((IF((PesoCuartoG/1000)=0,0,INT((KgVerde*(1-MermaTostado))/(PesoCuartoG/1000))))*PrecioVentaCuarto)-(KgVerde*$A16+(IF(MaquilaSobre="Tostado",(KgVerde*(1-MermaTostado)),KgVerde))*MaquilaKg+(ROUNDUP((IF((PesoCuartoG/1000)=0,0,INT((KgVerde*(1-MermaTostado))/(PesoCuartoG/1000))))*(1+MermaEmpaque),0))*(D$13+PrecioEtiqueta)+(IF((PesoCuartoG/1000)=0,0,INT((KgVerde*(1-MermaTostado))/(PesoCuartoG/1000))))*MOEmpaqueCuarto+FleteLote+OtrosLote) | E16: =((IF((PesoCuartoG/1000)=0,0,INT((KgVerde*(1-MermaTostado))/(PesoCuartoG/1000))))*PrecioVentaCuarto)-(KgVerde*$A16+(IF(MaquilaSobre="Tostado",(KgVerde*(1-MermaTostado)),KgVerde))*MaquilaKg+(ROUNDUP((IF((PesoCuartoG/1000)=0,0,INT((KgVerde*(1-MermaTostado))/(PesoCuartoG/1000))))*(1+MermaEmpaque),0))*(E$13+PrecioEtiqueta)+(IF((PesoCuartoG/1000)=0,0,INT((KgVerde*(1-MermaTostado))/(PesoCuartoG/1000))))*MOEmpaqueCuarto+FleteLote+OtrosLote) | F16: =((IF((PesoCuartoG/1000)=0,0,INT((KgVerde*(1-MermaTostado))/(PesoCuartoG/1000))))*PrecioVentaCuarto)-(KgVerde*$A16+(IF(MaquilaSobre="Tostado",(KgVerde*(1-MermaTostado)),KgVerde))*MaquilaKg+(ROUNDUP((IF((PesoCuartoG/1000)=0,0,INT((KgVerde*(1-MermaTostado))/(PesoCuartoG/1000))))*(1+MermaEmpaque),0))*(F$13+PrecioEtiqueta)+(IF((PesoCuartoG/1000)=0,0,INT((KgVerde*(1-MermaTostado))/(PesoCuartoG/1000))))*MOEmpaqueCuarto+FleteLote+OtrosLote)
A17: =EscD | B17: =((IF((PesoCuartoG/1000)=0,0,INT((KgVerde*(1-MermaTostado))/(PesoCuartoG/1000))))*PrecioVentaCuarto)-(KgVerde*$A17+(IF(MaquilaSobre="Tostado",(KgVerde*(1-MermaTostado)),KgVerde))*MaquilaKg+(ROUNDUP((IF((PesoCuartoG/1000)=0,0,INT((KgVerde*(1-MermaTostado))/(PesoCuartoG/1000))))*(1+MermaEmpaque),0))*(B$13+PrecioEtiqueta)+(IF((PesoCuartoG/1000)=0,0,INT((KgVerde*(1-MermaTostado))/(PesoCuartoG/1000))))*MOEmpaqueCuarto+FleteLote+OtrosLote) | C17: =((IF((PesoCuartoG/1000)=0,0,INT((KgVerde*(1-MermaTostado))/(PesoCuartoG/1000))))*PrecioVentaCuarto)-(KgVerde*$A17+(IF(MaquilaSobre="Tostado",(KgVerde*(1-MermaTostado)),KgVerde))*MaquilaKg+(ROUNDUP((IF((PesoCuartoG/1000)=0,0,INT((KgVerde*(1-MermaTostado))/(PesoCuartoG/1000))))*(1+MermaEmpaque),0))*(C$13+PrecioEtiqueta)+(IF((PesoCuartoG/1000)=0,0,INT((KgVerde*(1-MermaTostado))/(PesoCuartoG/1000))))*MOEmpaqueCuarto+FleteLote+OtrosLote) | D17: =((IF((PesoCuartoG/1000)=0,0,INT((KgVerde*(1-MermaTostado))/(PesoCuartoG/1000))))*PrecioVentaCuarto)-(KgVerde*$A17+(IF(MaquilaSobre="Tostado",(KgVerde*(1-MermaTostado)),KgVerde))*MaquilaKg+(ROUNDUP((IF((PesoCuartoG/1000)=0,0,INT((KgVerde*(1-MermaTostado))/(PesoCuartoG/1000))))*(1+MermaEmpaque),0))*(D$13+PrecioEtiqueta)+(IF((PesoCuartoG/1000)=0,0,INT((KgVerde*(1-MermaTostado))/(PesoCuartoG/1000))))*MOEmpaqueCuarto+FleteLote+OtrosLote) | E17: =((IF((PesoCuartoG/1000)=0,0,INT((KgVerde*(1-MermaTostado))/(PesoCuartoG/1000))))*PrecioVentaCuarto)-(KgVerde*$A17+(IF(MaquilaSobre="Tostado",(KgVerde*(1-MermaTostado)),KgVerde))*MaquilaKg+(ROUNDUP((IF((PesoCuartoG/1000)=0,0,INT((KgVerde*(1-MermaTostado))/(PesoCuartoG/1000))))*(1+MermaEmpaque),0))*(E$13+PrecioEtiqueta)+(IF((PesoCuartoG/1000)=0,0,INT((KgVerde*(1-MermaTostado))/(PesoCuartoG/1000))))*MOEmpaqueCuarto+FleteLote+OtrosLote) | F17: =((IF((PesoCuartoG/1000)=0,0,INT((KgVerde*(1-MermaTostado))/(PesoCuartoG/1000))))*PrecioVentaCuarto)-(KgVerde*$A17+(IF(MaquilaSobre="Tostado",(KgVerde*(1-MermaTostado)),KgVerde))*MaquilaKg+(ROUNDUP((IF((PesoCuartoG/1000)=0,0,INT((KgVerde*(1-MermaTostado))/(PesoCuartoG/1000))))*(1+MermaEmpaque),0))*(F$13+PrecioEtiqueta)+(IF((PesoCuartoG/1000)=0,0,INT((KgVerde*(1-MermaTostado))/(PesoCuartoG/1000))))*MOEmpaqueCuarto+FleteLote+OtrosLote)
A18: =EscE | B18: =((IF((PesoCuartoG/1000)=0,0,INT((KgVerde*(1-MermaTostado))/(PesoCuartoG/1000))))*PrecioVentaCuarto)-(KgVerde*$A18+(IF(MaquilaSobre="Tostado",(KgVerde*(1-MermaTostado)),KgVerde))*MaquilaKg+(ROUNDUP((IF((PesoCuartoG/1000)=0,0,INT((KgVerde*(1-MermaTostado))/(PesoCuartoG/1000))))*(1+MermaEmpaque),0))*(B$13+PrecioEtiqueta)+(IF((PesoCuartoG/1000)=0,0,INT((KgVerde*(1-MermaTostado))/(PesoCuartoG/1000))))*MOEmpaqueCuarto+FleteLote+OtrosLote) | C18: =((IF((PesoCuartoG/1000)=0,0,INT((KgVerde*(1-MermaTostado))/(PesoCuartoG/1000))))*PrecioVentaCuarto)-(KgVerde*$A18+(IF(MaquilaSobre="Tostado",(KgVerde*(1-MermaTostado)),KgVerde))*MaquilaKg+(ROUNDUP((IF((PesoCuartoG/1000)=0,0,INT((KgVerde*(1-MermaTostado))/(PesoCuartoG/1000))))*(1+MermaEmpaque),0))*(C$13+PrecioEtiqueta)+(IF((PesoCuartoG/1000)=0,0,INT((KgVerde*(1-MermaTostado))/(PesoCuartoG/1000))))*MOEmpaqueCuarto+FleteLote+OtrosLote) | D18: =((IF((PesoCuartoG/1000)=0,0,INT((KgVerde*(1-MermaTostado))/(PesoCuartoG/1000))))*PrecioVentaCuarto)-(KgVerde*$A18+(IF(MaquilaSobre="Tostado",(KgVerde*(1-MermaTostado)),KgVerde))*MaquilaKg+(ROUNDUP((IF((PesoCuartoG/1000)=0,0,INT((KgVerde*(1-MermaTostado))/(PesoCuartoG/1000))))*(1+MermaEmpaque),0))*(D$13+PrecioEtiqueta)+(IF((PesoCuartoG/1000)=0,0,INT((KgVerde*(1-MermaTostado))/(PesoCuartoG/1000))))*MOEmpaqueCuarto+FleteLote+OtrosLote) | E18: =((IF((PesoCuartoG/1000)=0,0,INT((KgVerde*(1-MermaTostado))/(PesoCuartoG/1000))))*PrecioVentaCuarto)-(KgVerde*$A18+(IF(MaquilaSobre="Tostado",(KgVerde*(1-MermaTostado)),KgVerde))*MaquilaKg+(ROUNDUP((IF((PesoCuartoG/1000)=0,0,INT((KgVerde*(1-MermaTostado))/(PesoCuartoG/1000))))*(1+MermaEmpaque),0))*(E$13+PrecioEtiqueta)+(IF((PesoCuartoG/1000)=0,0,INT((KgVerde*(1-MermaTostado))/(PesoCuartoG/1000))))*MOEmpaqueCuarto+FleteLote+OtrosLote) | F18: =((IF((PesoCuartoG/1000)=0,0,INT((KgVerde*(1-MermaTostado))/(PesoCuartoG/1000))))*PrecioVentaCuarto)-(KgVerde*$A18+(IF(MaquilaSobre="Tostado",(KgVerde*(1-MermaTostado)),KgVerde))*MaquilaKg+(ROUNDUP((IF((PesoCuartoG/1000)=0,0,INT((KgVerde*(1-MermaTostado))/(PesoCuartoG/1000))))*(1+MermaEmpaque),0))*(F$13+PrecioEtiqueta)+(IF((PesoCuartoG/1000)=0,0,INT((KgVerde*(1-MermaTostado))/(PesoCuartoG/1000))))*MOEmpaqueCuarto+FleteLote+OtrosLote)
A20: 3. Margen neto: precio verde × precio de venta del cuarto (si negocias otro precio con Tostado Club)
A21: Verde \ Venta | B21: 5000 | C21: 5500 | D21: 6000 | E21: 6500 | F21: 7000 | G21: Hoy estás en $6.000. Útil si pides alza o te bajan el precio.
A22: =EscA | B22: =IF(((IF((PesoCuartoG/1000)=0,0,INT((KgVerde*(1-MermaTostado))/(PesoCuartoG/1000))))*B$21)=0,0,(((IF((PesoCuartoG/1000)=0,0,INT((KgVerde*(1-MermaTostado))/(PesoCuartoG/1000))))*B$21)-(KgVerde*$A22+(IF(MaquilaSobre="Tostado",(KgVerde*(1-MermaTostado)),KgVerde))*MaquilaKg+(ROUNDUP((IF((PesoCuartoG/1000)=0,0,INT((KgVerde*(1-MermaTostado))/(PesoCuartoG/1000))))*(1+MermaEmpaque),0))*(PrecioBolsa+PrecioEtiqueta)+(IF((PesoCuartoG/1000)=0,0,INT((KgVerde*(1-MermaTostado))/(PesoCuartoG/1000))))*MOEmpaqueCuarto+FleteLote+OtrosLote))/((IF((PesoCuartoG/1000)=0,0,INT((KgVerde*(1-MermaTostado))/(PesoCuartoG/1000))))*B$21)) | C22: =IF(((IF((PesoCuartoG/1000)=0,0,INT((KgVerde*(1-MermaTostado))/(PesoCuartoG/1000))))*C$21)=0,0,(((IF((PesoCuartoG/1000)=0,0,INT((KgVerde*(1-MermaTostado))/(PesoCuartoG/1000))))*C$21)-(KgVerde*$A22+(IF(MaquilaSobre="Tostado",(KgVerde*(1-MermaTostado)),KgVerde))*MaquilaKg+(ROUNDUP((IF((PesoCuartoG/1000)=0,0,INT((KgVerde*(1-MermaTostado))/(PesoCuartoG/1000))))*(1+MermaEmpaque),0))*(PrecioBolsa+PrecioEtiqueta)+(IF((PesoCuartoG/1000)=0,0,INT((KgVerde*(1-MermaTostado))/(PesoCuartoG/1000))))*MOEmpaqueCuarto+FleteLote+OtrosLote))/((IF((PesoCuartoG/1000)=0,0,INT((KgVerde*(1-MermaTostado))/(PesoCuartoG/1000))))*C$21)) | D22: =IF(((IF((PesoCuartoG/1000)=0,0,INT((KgVerde*(1-MermaTostado))/(PesoCuartoG/1000))))*D$21)=0,0,(((IF((PesoCuartoG/1000)=0,0,INT((KgVerde*(1-MermaTostado))/(PesoCuartoG/1000))))*D$21)-(KgVerde*$A22+(IF(MaquilaSobre="Tostado",(KgVerde*(1-MermaTostado)),KgVerde))*MaquilaKg+(ROUNDUP((IF((PesoCuartoG/1000)=0,0,INT((KgVerde*(1-MermaTostado))/(PesoCuartoG/1000))))*(1+MermaEmpaque),0))*(PrecioBolsa+PrecioEtiqueta)+(IF((PesoCuartoG/1000)=0,0,INT((KgVerde*(1-MermaTostado))/(PesoCuartoG/1000))))*MOEmpaqueCuarto+FleteLote+OtrosLote))/((IF((PesoCuartoG/1000)=0,0,INT((KgVerde*(1-MermaTostado))/(PesoCuartoG/1000))))*D$21)) | E22: =IF(((IF((PesoCuartoG/1000)=0,0,INT((KgVerde*(1-MermaTostado))/(PesoCuartoG/1000))))*E$21)=0,0,(((IF((PesoCuartoG/1000)=0,0,INT((KgVerde*(1-MermaTostado))/(PesoCuartoG/1000))))*E$21)-(KgVerde*$A22+(IF(MaquilaSobre="Tostado",(KgVerde*(1-MermaTostado)),KgVerde))*MaquilaKg+(ROUNDUP((IF((PesoCuartoG/1000)=0,0,INT((KgVerde*(1-MermaTostado))/(PesoCuartoG/1000))))*(1+MermaEmpaque),0))*(PrecioBolsa+PrecioEtiqueta)+(IF((PesoCuartoG/1000)=0,0,INT((KgVerde*(1-MermaTostado))/(PesoCuartoG/1000))))*MOEmpaqueCuarto+FleteLote+OtrosLote))/((IF((PesoCuartoG/1000)=0,0,INT((KgVerde*(1-MermaTostado))/(PesoCuartoG/1000))))*E$21)) | F22: =IF(((IF((PesoCuartoG/1000)=0,0,INT((KgVerde*(1-MermaTostado))/(PesoCuartoG/1000))))*F$21)=0,0,(((IF((PesoCuartoG/1000)=0,0,INT((KgVerde*(1-MermaTostado))/(PesoCuartoG/1000))))*F$21)-(KgVerde*$A22+(IF(MaquilaSobre="Tostado",(KgVerde*(1-MermaTostado)),KgVerde))*MaquilaKg+(ROUNDUP((IF((PesoCuartoG/1000)=0,0,INT((KgVerde*(1-MermaTostado))/(PesoCuartoG/1000))))*(1+MermaEmpaque),0))*(PrecioBolsa+PrecioEtiqueta)+(IF((PesoCuartoG/1000)=0,0,INT((KgVerde*(1-MermaTostado))/(PesoCuartoG/1000))))*MOEmpaqueCuarto+FleteLote+OtrosLote))/((IF((PesoCuartoG/1000)=0,0,INT((KgVerde*(1-MermaTostado))/(PesoCuartoG/1000))))*F$21))
A23: =EscB | B23: =IF(((IF((PesoCuartoG/1000)=0,0,INT((KgVerde*(1-MermaTostado))/(PesoCuartoG/1000))))*B$21)=0,0,(((IF((PesoCuartoG/1000)=0,0,INT((KgVerde*(1-MermaTostado))/(PesoCuartoG/1000))))*B$21)-(KgVerde*$A23+(IF(MaquilaSobre="Tostado",(KgVerde*(1-MermaTostado)),KgVerde))*MaquilaKg+(ROUNDUP((IF((PesoCuartoG/1000)=0,0,INT((KgVerde*(1-MermaTostado))/(PesoCuartoG/1000))))*(1+MermaEmpaque),0))*(PrecioBolsa+PrecioEtiqueta)+(IF((PesoCuartoG/1000)=0,0,INT((KgVerde*(1-MermaTostado))/(PesoCuartoG/1000))))*MOEmpaqueCuarto+FleteLote+OtrosLote))/((IF((PesoCuartoG/1000)=0,0,INT((KgVerde*(1-MermaTostado))/(PesoCuartoG/1000))))*B$21)) | C23: =IF(((IF((PesoCuartoG/1000)=0,0,INT((KgVerde*(1-MermaTostado))/(PesoCuartoG/1000))))*C$21)=0,0,(((IF((PesoCuartoG/1000)=0,0,INT((KgVerde*(1-MermaTostado))/(PesoCuartoG/1000))))*C$21)-(KgVerde*$A23+(IF(MaquilaSobre="Tostado",(KgVerde*(1-MermaTostado)),KgVerde))*MaquilaKg+(ROUNDUP((IF((PesoCuartoG/1000)=0,0,INT((KgVerde*(1-MermaTostado))/(PesoCuartoG/1000))))*(1+MermaEmpaque),0))*(PrecioBolsa+PrecioEtiqueta)+(IF((PesoCuartoG/1000)=0,0,INT((KgVerde*(1-MermaTostado))/(PesoCuartoG/1000))))*MOEmpaqueCuarto+FleteLote+OtrosLote))/((IF((PesoCuartoG/1000)=0,0,INT((KgVerde*(1-MermaTostado))/(PesoCuartoG/1000))))*C$21)) | D23: =IF(((IF((PesoCuartoG/1000)=0,0,INT((KgVerde*(1-MermaTostado))/(PesoCuartoG/1000))))*D$21)=0,0,(((IF((PesoCuartoG/1000)=0,0,INT((KgVerde*(1-MermaTostado))/(PesoCuartoG/1000))))*D$21)-(KgVerde*$A23+(IF(MaquilaSobre="Tostado",(KgVerde*(1-MermaTostado)),KgVerde))*MaquilaKg+(ROUNDUP((IF((PesoCuartoG/1000)=0,0,INT((KgVerde*(1-MermaTostado))/(PesoCuartoG/1000))))*(1+MermaEmpaque),0))*(PrecioBolsa+PrecioEtiqueta)+(IF((PesoCuartoG/1000)=0,0,INT((KgVerde*(1-MermaTostado))/(PesoCuartoG/1000))))*MOEmpaqueCuarto+FleteLote+OtrosLote))/((IF((PesoCuartoG/1000)=0,0,INT((KgVerde*(1-MermaTostado))/(PesoCuartoG/1000))))*D$21)) | E23: =IF(((IF((PesoCuartoG/1000)=0,0,INT((KgVerde*(1-MermaTostado))/(PesoCuartoG/1000))))*E$21)=0,0,(((IF((PesoCuartoG/1000)=0,0,INT((KgVerde*(1-MermaTostado))/(PesoCuartoG/1000))))*E$21)-(KgVerde*$A23+(IF(MaquilaSobre="Tostado",(KgVerde*(1-MermaTostado)),KgVerde))*MaquilaKg+(ROUNDUP((IF((PesoCuartoG/1000)=0,0,INT((KgVerde*(1-MermaTostado))/(PesoCuartoG/1000))))*(1+MermaEmpaque),0))*(PrecioBolsa+PrecioEtiqueta)+(IF((PesoCuartoG/1000)=0,0,INT((KgVerde*(1-MermaTostado))/(PesoCuartoG/1000))))*MOEmpaqueCuarto+FleteLote+OtrosLote))/((IF((PesoCuartoG/1000)=0,0,INT((KgVerde*(1-MermaTostado))/(PesoCuartoG/1000))))*E$21)) | F23: =IF(((IF((PesoCuartoG/1000)=0,0,INT((KgVerde*(1-MermaTostado))/(PesoCuartoG/1000))))*F$21)=0,0,(((IF((PesoCuartoG/1000)=0,0,INT((KgVerde*(1-MermaTostado))/(PesoCuartoG/1000))))*F$21)-(KgVerde*$A23+(IF(MaquilaSobre="Tostado",(KgVerde*(1-MermaTostado)),KgVerde))*MaquilaKg+(ROUNDUP((IF((PesoCuartoG/1000)=0,0,INT((KgVerde*(1-MermaTostado))/(PesoCuartoG/1000))))*(1+MermaEmpaque),0))*(PrecioBolsa+PrecioEtiqueta)+(IF((PesoCuartoG/1000)=0,0,INT((KgVerde*(1-MermaTostado))/(PesoCuartoG/1000))))*MOEmpaqueCuarto+FleteLote+OtrosLote))/((IF((PesoCuartoG/1000)=0,0,INT((KgVerde*(1-MermaTostado))/(PesoCuartoG/1000))))*F$21))
A24: =EscC | B24: =IF(((IF((PesoCuartoG/1000)=0,0,INT((KgVerde*(1-MermaTostado))/(PesoCuartoG/1000))))*B$21)=0,0,(((IF((PesoCuartoG/1000)=0,0,INT((KgVerde*(1-MermaTostado))/(PesoCuartoG/1000))))*B$21)-(KgVerde*$A24+(IF(MaquilaSobre="Tostado",(KgVerde*(1-MermaTostado)),KgVerde))*MaquilaKg+(ROUNDUP((IF((PesoCuartoG/1000)=0,0,INT((KgVerde*(1-MermaTostado))/(PesoCuartoG/1000))))*(1+MermaEmpaque),0))*(PrecioBolsa+PrecioEtiqueta)+(IF((PesoCuartoG/1000)=0,0,INT((KgVerde*(1-MermaTostado))/(PesoCuartoG/1000))))*MOEmpaqueCuarto+FleteLote+OtrosLote))/((IF((PesoCuartoG/1000)=0,0,INT((KgVerde*(1-MermaTostado))/(PesoCuartoG/1000))))*B$21)) | C24: =IF(((IF((PesoCuartoG/1000)=0,0,INT((KgVerde*(1-MermaTostado))/(PesoCuartoG/1000))))*C$21)=0,0,(((IF((PesoCuartoG/1000)=0,0,INT((KgVerde*(1-MermaTostado))/(PesoCuartoG/1000))))*C$21)-(KgVerde*$A24+(IF(MaquilaSobre="Tostado",(KgVerde*(1-MermaTostado)),KgVerde))*MaquilaKg+(ROUNDUP((IF((PesoCuartoG/1000)=0,0,INT((KgVerde*(1-MermaTostado))/(PesoCuartoG/1000))))*(1+MermaEmpaque),0))*(PrecioBolsa+PrecioEtiqueta)+(IF((PesoCuartoG/1000)=0,0,INT((KgVerde*(1-MermaTostado))/(PesoCuartoG/1000))))*MOEmpaqueCuarto+FleteLote+OtrosLote))/((IF((PesoCuartoG/1000)=0,0,INT((KgVerde*(1-MermaTostado))/(PesoCuartoG/1000))))*C$21)) | D24: =IF(((IF((PesoCuartoG/1000)=0,0,INT((KgVerde*(1-MermaTostado))/(PesoCuartoG/1000))))*D$21)=0,0,(((IF((PesoCuartoG/1000)=0,0,INT((KgVerde*(1-MermaTostado))/(PesoCuartoG/1000))))*D$21)-(KgVerde*$A24+(IF(MaquilaSobre="Tostado",(KgVerde*(1-MermaTostado)),KgVerde))*MaquilaKg+(ROUNDUP((IF((PesoCuartoG/1000)=0,0,INT((KgVerde*(1-MermaTostado))/(PesoCuartoG/1000))))*(1+MermaEmpaque),0))*(PrecioBolsa+PrecioEtiqueta)+(IF((PesoCuartoG/1000)=0,0,INT((KgVerde*(1-MermaTostado))/(PesoCuartoG/1000))))*MOEmpaqueCuarto+FleteLote+OtrosLote))/((IF((PesoCuartoG/1000)=0,0,INT((KgVerde*(1-MermaTostado))/(PesoCuartoG/1000))))*D$21)) | E24: =IF(((IF((PesoCuartoG/1000)=0,0,INT((KgVerde*(1-MermaTostado))/(PesoCuartoG/1000))))*E$21)=0,0,(((IF((PesoCuartoG/1000)=0,0,INT((KgVerde*(1-MermaTostado))/(PesoCuartoG/1000))))*E$21)-(KgVerde*$A24+(IF(MaquilaSobre="Tostado",(KgVerde*(1-MermaTostado)),KgVerde))*MaquilaKg+(ROUNDUP((IF((PesoCuartoG/1000)=0,0,INT((KgVerde*(1-MermaTostado))/(PesoCuartoG/1000))))*(1+MermaEmpaque),0))*(PrecioBolsa+PrecioEtiqueta)+(IF((PesoCuartoG/1000)=0,0,INT((KgVerde*(1-MermaTostado))/(PesoCuartoG/1000))))*MOEmpaqueCuarto+FleteLote+OtrosLote))/((IF((PesoCuartoG/1000)=0,0,INT((KgVerde*(1-MermaTostado))/(PesoCuartoG/1000))))*E$21)) | F24: =IF(((IF((PesoCuartoG/1000)=0,0,INT((KgVerde*(1-MermaTostado))/(PesoCuartoG/1000))))*F$21)=0,0,(((IF((PesoCuartoG/1000)=0,0,INT((KgVerde*(1-MermaTostado))/(PesoCuartoG/1000))))*F$21)-(KgVerde*$A24+(IF(MaquilaSobre="Tostado",(KgVerde*(1-MermaTostado)),KgVerde))*MaquilaKg+(ROUNDUP((IF((PesoCuartoG/1000)=0,0,INT((KgVerde*(1-MermaTostado))/(PesoCuartoG/1000))))*(1+MermaEmpaque),0))*(PrecioBolsa+PrecioEtiqueta)+(IF((PesoCuartoG/1000)=0,0,INT((KgVerde*(1-MermaTostado))/(PesoCuartoG/1000))))*MOEmpaqueCuarto+FleteLote+OtrosLote))/((IF((PesoCuartoG/1000)=0,0,INT((KgVerde*(1-MermaTostado))/(PesoCuartoG/1000))))*F$21))
A25: =EscD | B25: =IF(((IF((PesoCuartoG/1000)=0,0,INT((KgVerde*(1-MermaTostado))/(PesoCuartoG/1000))))*B$21)=0,0,(((IF((PesoCuartoG/1000)=0,0,INT((KgVerde*(1-MermaTostado))/(PesoCuartoG/1000))))*B$21)-(KgVerde*$A25+(IF(MaquilaSobre="Tostado",(KgVerde*(1-MermaTostado)),KgVerde))*MaquilaKg+(ROUNDUP((IF((PesoCuartoG/1000)=0,0,INT((KgVerde*(1-MermaTostado))/(PesoCuartoG/1000))))*(1+MermaEmpaque),0))*(PrecioBolsa+PrecioEtiqueta)+(IF((PesoCuartoG/1000)=0,0,INT((KgVerde*(1-MermaTostado))/(PesoCuartoG/1000))))*MOEmpaqueCuarto+FleteLote+OtrosLote))/((IF((PesoCuartoG/1000)=0,0,INT((KgVerde*(1-MermaTostado))/(PesoCuartoG/1000))))*B$21)) | C25: =IF(((IF((PesoCuartoG/1000)=0,0,INT((KgVerde*(1-MermaTostado))/(PesoCuartoG/1000))))*C$21)=0,0,(((IF((PesoCuartoG/1000)=0,0,INT((KgVerde*(1-MermaTostado))/(PesoCuartoG/1000))))*C$21)-(KgVerde*$A25+(IF(MaquilaSobre="Tostado",(KgVerde*(1-MermaTostado)),KgVerde))*MaquilaKg+(ROUNDUP((IF((PesoCuartoG/1000)=0,0,INT((KgVerde*(1-MermaTostado))/(PesoCuartoG/1000))))*(1+MermaEmpaque),0))*(PrecioBolsa+PrecioEtiqueta)+(IF((PesoCuartoG/1000)=0,0,INT((KgVerde*(1-MermaTostado))/(PesoCuartoG/1000))))*MOEmpaqueCuarto+FleteLote+OtrosLote))/((IF((PesoCuartoG/1000)=0,0,INT((KgVerde*(1-MermaTostado))/(PesoCuartoG/1000))))*C$21)) | D25: =IF(((IF((PesoCuartoG/1000)=0,0,INT((KgVerde*(1-MermaTostado))/(PesoCuartoG/1000))))*D$21)=0,0,(((IF((PesoCuartoG/1000)=0,0,INT((KgVerde*(1-MermaTostado))/(PesoCuartoG/1000))))*D$21)-(KgVerde*$A25+(IF(MaquilaSobre="Tostado",(KgVerde*(1-MermaTostado)),KgVerde))*MaquilaKg+(ROUNDUP((IF((PesoCuartoG/1000)=0,0,INT((KgVerde*(1-MermaTostado))/(PesoCuartoG/1000))))*(1+MermaEmpaque),0))*(PrecioBolsa+PrecioEtiqueta)+(IF((PesoCuartoG/1000)=0,0,INT((KgVerde*(1-MermaTostado))/(PesoCuartoG/1000))))*MOEmpaqueCuarto+FleteLote+OtrosLote))/((IF((PesoCuartoG/1000)=0,0,INT((KgVerde*(1-MermaTostado))/(PesoCuartoG/1000))))*D$21)) | E25: =IF(((IF((PesoCuartoG/1000)=0,0,INT((KgVerde*(1-MermaTostado))/(PesoCuartoG/1000))))*E$21)=0,0,(((IF((PesoCuartoG/1000)=0,0,INT((KgVerde*(1-MermaTostado))/(PesoCuartoG/1000))))*E$21)-(KgVerde*$A25+(IF(MaquilaSobre="Tostado",(KgVerde*(1-MermaTostado)),KgVerde))*MaquilaKg+(ROUNDUP((IF((PesoCuartoG/1000)=0,0,INT((KgVerde*(1-MermaTostado))/(PesoCuartoG/1000))))*(1+MermaEmpaque),0))*(PrecioBolsa+PrecioEtiqueta)+(IF((PesoCuartoG/1000)=0,0,INT((KgVerde*(1-MermaTostado))/(PesoCuartoG/1000))))*MOEmpaqueCuarto+FleteLote+OtrosLote))/((IF((PesoCuartoG/1000)=0,0,INT((KgVerde*(1-MermaTostado))/(PesoCuartoG/1000))))*E$21)) | F25: =IF(((IF((PesoCuartoG/1000)=0,0,INT((KgVerde*(1-MermaTostado))/(PesoCuartoG/1000))))*F$21)=0,0,(((IF((PesoCuartoG/1000)=0,0,INT((KgVerde*(1-MermaTostado))/(PesoCuartoG/1000))))*F$21)-(KgVerde*$A25+(IF(MaquilaSobre="Tostado",(KgVerde*(1-MermaTostado)),KgVerde))*MaquilaKg+(ROUNDUP((IF((PesoCuartoG/1000)=0,0,INT((KgVerde*(1-MermaTostado))/(PesoCuartoG/1000))))*(1+MermaEmpaque),0))*(PrecioBolsa+PrecioEtiqueta)+(IF((PesoCuartoG/1000)=0,0,INT((KgVerde*(1-MermaTostado))/(PesoCuartoG/1000))))*MOEmpaqueCuarto+FleteLote+OtrosLote))/((IF((PesoCuartoG/1000)=0,0,INT((KgVerde*(1-MermaTostado))/(PesoCuartoG/1000))))*F$21))
A26: =EscE | B26: =IF(((IF((PesoCuartoG/1000)=0,0,INT((KgVerde*(1-MermaTostado))/(PesoCuartoG/1000))))*B$21)=0,0,(((IF((PesoCuartoG/1000)=0,0,INT((KgVerde*(1-MermaTostado))/(PesoCuartoG/1000))))*B$21)-(KgVerde*$A26+(IF(MaquilaSobre="Tostado",(KgVerde*(1-MermaTostado)),KgVerde))*MaquilaKg+(ROUNDUP((IF((PesoCuartoG/1000)=0,0,INT((KgVerde*(1-MermaTostado))/(PesoCuartoG/1000))))*(1+MermaEmpaque),0))*(PrecioBolsa+PrecioEtiqueta)+(IF((PesoCuartoG/1000)=0,0,INT((KgVerde*(1-MermaTostado))/(PesoCuartoG/1000))))*MOEmpaqueCuarto+FleteLote+OtrosLote))/((IF((PesoCuartoG/1000)=0,0,INT((KgVerde*(1-MermaTostado))/(PesoCuartoG/1000))))*B$21)) | C26: =IF(((IF((PesoCuartoG/1000)=0,0,INT((KgVerde*(1-MermaTostado))/(PesoCuartoG/1000))))*C$21)=0,0,(((IF((PesoCuartoG/1000)=0,0,INT((KgVerde*(1-MermaTostado))/(PesoCuartoG/1000))))*C$21)-(KgVerde*$A26+(IF(MaquilaSobre="Tostado",(KgVerde*(1-MermaTostado)),KgVerde))*MaquilaKg+(ROUNDUP((IF((PesoCuartoG/1000)=0,0,INT((KgVerde*(1-MermaTostado))/(PesoCuartoG/1000))))*(1+MermaEmpaque),0))*(PrecioBolsa+PrecioEtiqueta)+(IF((PesoCuartoG/1000)=0,0,INT((KgVerde*(1-MermaTostado))/(PesoCuartoG/1000))))*MOEmpaqueCuarto+FleteLote+OtrosLote))/((IF((PesoCuartoG/1000)=0,0,INT((KgVerde*(1-MermaTostado))/(PesoCuartoG/1000))))*C$21)) | D26: =IF(((IF((PesoCuartoG/1000)=0,0,INT((KgVerde*(1-MermaTostado))/(PesoCuartoG/1000))))*D$21)=0,0,(((IF((PesoCuartoG/1000)=0,0,INT((KgVerde*(1-MermaTostado))/(PesoCuartoG/1000))))*D$21)-(KgVerde*$A26+(IF(MaquilaSobre="Tostado",(KgVerde*(1-MermaTostado)),KgVerde))*MaquilaKg+(ROUNDUP((IF((PesoCuartoG/1000)=0,0,INT((KgVerde*(1-MermaTostado))/(PesoCuartoG/1000))))*(1+MermaEmpaque),0))*(PrecioBolsa+PrecioEtiqueta)+(IF((PesoCuartoG/1000)=0,0,INT((KgVerde*(1-MermaTostado))/(PesoCuartoG/1000))))*MOEmpaqueCuarto+FleteLote+OtrosLote))/((IF((PesoCuartoG/1000)=0,0,INT((KgVerde*(1-MermaTostado))/(PesoCuartoG/1000))))*D$21)) | E26: =IF(((IF((PesoCuartoG/1000)=0,0,INT((KgVerde*(1-MermaTostado))/(PesoCuartoG/1000))))*E$21)=0,0,(((IF((PesoCuartoG/1000)=0,0,INT((KgVerde*(1-MermaTostado))/(PesoCuartoG/1000))))*E$21)-(KgVerde*$A26+(IF(MaquilaSobre="Tostado",(KgVerde*(1-MermaTostado)),KgVerde))*MaquilaKg+(ROUNDUP((IF((PesoCuartoG/1000)=0,0,INT((KgVerde*(1-MermaTostado))/(PesoCuartoG/1000))))*(1+MermaEmpaque),0))*(PrecioBolsa+PrecioEtiqueta)+(IF((PesoCuartoG/1000)=0,0,INT((KgVerde*(1-MermaTostado))/(PesoCuartoG/1000))))*MOEmpaqueCuarto+FleteLote+OtrosLote))/((IF((PesoCuartoG/1000)=0,0,INT((KgVerde*(1-MermaTostado))/(PesoCuartoG/1000))))*E$21)) | F26: =IF(((IF((PesoCuartoG/1000)=0,0,INT((KgVerde*(1-MermaTostado))/(PesoCuartoG/1000))))*F$21)=0,0,(((IF((PesoCuartoG/1000)=0,0,INT((KgVerde*(1-MermaTostado))/(PesoCuartoG/1000))))*F$21)-(KgVerde*$A26+(IF(MaquilaSobre="Tostado",(KgVerde*(1-MermaTostado)),KgVerde))*MaquilaKg+(ROUNDUP((IF((PesoCuartoG/1000)=0,0,INT((KgVerde*(1-MermaTostado))/(PesoCuartoG/1000))))*(1+MermaEmpaque),0))*(PrecioBolsa+PrecioEtiqueta)+(IF((PesoCuartoG/1000)=0,0,INT((KgVerde*(1-MermaTostado))/(PesoCuartoG/1000))))*MOEmpaqueCuarto+FleteLote+OtrosLote))/((IF((PesoCuartoG/1000)=0,0,INT((KgVerde*(1-MermaTostado))/(PesoCuartoG/1000))))*F$21))
A28: Qué no está modelado (y puede mover el número): merma de calidad / quiebre, molienda, cajas master, financiamiento si Tostado Club paga a 30/60 días, mermas de inventario, y tu tiempo de coordinación. Si el primer lote real da otra merma, cámbiala en Parámetros y estas tablas se actualizan.

Sheet Calc
A1: Clave | B1: Valor
A2: KgTostado | B2: =KgVerde*(1-MermaTostado)
A3: KgPorCuarto | B3: =PesoCuartoG/1000
A4: Cuartos | B4: =IF(B3=0,0,INT(B2/B3))
A5: SobranteG | B5: =(B2-B4*B3)*1000
A6: Bolsas | B6: =ROUNDUP(B4*(1+MermaEmpaque),0)
A7: KgMaquila | B7: =IF(MaquilaSobre="Tostado",B2,KgVerde)
A9: CostoVerde | B9: =KgVerde*PrecioVerdeBase
A10: CostoMaquila | B10: =B7*MaquilaKg
A11: CostoBolsas | B11: =B6*PrecioBolsa
A12: CostoEtiquetas | B12: =B6*PrecioEtiqueta
A13: CostoMO | B13: =B4*MOEmpaqueCuarto
A14: CostoFlete | B14: =FleteLote
A15: CostoOtros | B15: =OtrosLote
A16: CostoTotal | B16: =B9+B10+B11+B12+B13+B14+B15
A17: CostoSinVerde | B17: =B16-B9
A19: VentaNeta | B19: =B4*PrecioVentaCuarto
A20: Utilidad | B20: =B19-B16
A21: Margen | B21: =IF(B19=0,0,B20/B19)
A22: Markup | B22: =IF(B16=0,0,B20/B16)
A24: CostoCuarto | B24: =IF(B4=0,0,B16/B4)
A25: CostoKgTostado | B25: =IF(B2=0,0,B16/B2)
A26: UtilidadCuarto | B26: =PrecioVentaCuarto-B24
A27: PrecioKgTostadoVenta | B27: =IF(B3=0,0,PrecioVentaCuarto/B3)
A29: IvaCredito | B29: =B16*IVA
A30: IvaDebito | B30: =B19*IVA
A31: IvaPagar | B31: =B30-B29
A32: CajaSalida | B32: =B16*(1+IVA)
A33: CajaEntrada | B33: =B19*(1+IVA)
A34: FlujoCaja | B34: =B33-B32
A36: PrecioVerdeMaxCero | B36: =IF(KgVerde=0,0,(B19-B17)/KgVerde)
A37: PrecioVerdeMaxObj | B37: =IF(KgVerde=0,0,(B19*(1-MargenObjetivo)-B17)/KgVerde)
A38: VentaMinCuarto | B38: =B24
A39: VentaMinObj | B39: =IF(1-MargenObjetivo=0,0,B24/(1-MargenObjetivo))
